[2024-03-29T16:29:16.553+0000] {taskinstance.py:1979} INFO - Dependencies all met for dep_context=non-requeueable deps ti=<TaskInstance: grobid_extraction.validate_data manual__2024-03-29T16:29:08.573716+00:00 [queued]>
[2024-03-29T16:29:16.572+0000] {taskinstance.py:1979} INFO - Dependencies all met for dep_context=requeueable deps ti=<TaskInstance: grobid_extraction.validate_data manual__2024-03-29T16:29:08.573716+00:00 [queued]>
[2024-03-29T16:29:16.574+0000] {taskinstance.py:2193} INFO - Starting attempt 1 of 1
[2024-03-29T16:29:16.600+0000] {taskinstance.py:2217} INFO - Executing <Task(PythonOperator): validate_data> on 2024-03-29 16:29:08.573716+00:00
[2024-03-29T16:29:16.611+0000] {standard_task_runner.py:60} INFO - Started process 857 to run task
[2024-03-29T16:29:16.616+0000] {standard_task_runner.py:87} INFO - Running: ['***', 'tasks', 'run', 'grobid_extraction', 'validate_data', 'manual__2024-03-29T16:29:08.573716+00:00', '--job-id', '184', '--raw', '--subdir', 'DAGS_FOLDER/grobid_extraction.py', '--cfg-path', '/tmp/tmpjptw25_b']
[2024-03-29T16:29:16.622+0000] {standard_task_runner.py:88} INFO - Job 184: Subtask validate_data
[2024-03-29T16:29:16.721+0000] {task_command.py:423} INFO - Running <TaskInstance: grobid_extraction.validate_data manual__2024-03-29T16:29:08.573716+00:00 [running]> on host 9bbf17010fdd
[2024-03-29T16:29:16.902+0000] {taskinstance.py:2513} INFO - Exporting env vars: AIRFLOW_CTX_DAG_EMAIL='shubhpatel2800@gmail.com' AIRFLOW_CTX_DAG_OWNER='***' AIRFLOW_CTX_DAG_ID='grobid_extraction' AIRFLOW_CTX_TASK_ID='validate_data' AIRFLOW_CTX_EXECUTION_DATE='2024-03-29T16:29:08.573716+00:00' AIRFLOW_CTX_TRY_NUMBER='1' AIRFLOW_CTX_DAG_RUN_ID='manual__2024-03-29T16:29:08.573716+00:00'
[2024-03-29T16:29:16.907+0000] {taskinstance.py:2731} ERROR - Task failed with exception
Traceback (most recent call last):
  File "/home/airflow/.local/lib/python3.8/site-packages/airflow/models/taskinstance.py", line 444, in _execute_task
    result = _execute_callable(context=context, **execute_callable_kwargs)
  File "/home/airflow/.local/lib/python3.8/site-packages/airflow/models/taskinstance.py", line 414, in _execute_callable
    return execute_callable(context=context, **execute_callable_kwargs)
  File "/home/airflow/.local/lib/python3.8/site-packages/airflow/operators/python.py", line 200, in execute
    return_value = self.execute_callable()
  File "/home/airflow/.local/lib/python3.8/site-packages/airflow/operators/python.py", line 217, in execute_callable
    return self.python_callable(*self.op_args, **self.op_kwargs)
  File "/opt/airflow/dags/grobid_extraction.py", line 132, in validate_and_structure_data
    document_section = DocumentSection(**section)
TypeError: ModelMetaclass object argument after ** must be a mapping, not str
[2024-03-29T16:29:16.934+0000] {taskinstance.py:1149} INFO - Marking task as FAILED. dag_id=grobid_extraction, task_id=validate_data, execution_date=20240329T162908, start_date=20240329T162916, end_date=20240329T162916
[2024-03-29T16:29:16.964+0000] {standard_task_runner.py:107} ERROR - Failed to execute job 184 for task validate_data (ModelMetaclass object argument after ** must be a mapping, not str; 857)
[2024-03-29T16:29:16.991+0000] {local_task_job_runner.py:234} INFO - Task exited with return code 1
[2024-03-29T16:29:17.042+0000] {taskinstance.py:3312} INFO - 0 downstream tasks scheduled from follow-on schedule check
